<?xml version="1.0"?>
<robot name="my_robot">

  <!-- Base Link -->
  <link name="base_link">
    <visual>
      <origin xyz="0 0 0" rpy="0 0 0"/>
      <geometry>
         <cylinder length="0.1" radius="0.1"/>         
      </geometry>
    </visual>
  </link>

  <!-- Box Link -->
  <link name="box_link_1">
    <visual>
      <origin xyz="0.5 0 0" rpy="0 0 0"/>
      <geometry>
        <box size="0.8 0.1 0.1"/>
      </geometry>
    </visual>
  </link>

  <!-- Joint connecting box_link to base_link -->
  <joint name="box_joint_1" type="revolute">
    <parent link="base_link"/>
    <child link="box_link_1"/>
    <origin xyz="0 0 0" rpy="0 0 0"/>
    <axis xyz="0 0 1"/>
    <limit lower="-3.14" upper="3.14" effort="10" velocity="0.5"/>
    <!-- Set the limits, effort, and velocity as per your requirements -->
  </joint>
 <!-- Box Link -->
  <link name="box_link_2">
    <visual>
      <origin xyz="0 0 0" rpy="0 0 0"/>
      <geometry>
         <cylinder length="0.1" radius="0.1"/>
      </geometry>
    </visual>
  </link>

  <!-- Joint connecting box_link to base_link -->
  <joint name="box_joint_2" type="revolute">
    <parent link="box_link_1"/>
    <child link="box_link_2"/>
    <origin xyz="0.9 0 0" rpy="0 0 0"/>
    <axis xyz="0 0 1"/>
    <limit lower="-3.14" upper="3.14" effort="1" velocity="0.4"/>
    <!-- Set the limits, effort, and velocity as per your requirements -->
  </joint>
  
  <link name="box_link_3">
    <visual>
      <origin xyz="0.5 0 0" rpy="0 0 0"/>
      <geometry>
        <box size="0.8 0.1 0.1"/>
      </geometry>
    </visual>
  </link>
  <joint name="box_joint_3" type="fixed">
       <parent link="box_link_2"/>
       <child link="box_link_3"/>
       <origin xyz="0 0 0"/>
  </joint>



</robot>
